__main__ - INFO: Ouverture du fichier
__main__ - ERROR: Ouverture impossible
Traceback (most recent call last):
  File "Traitement3.py", line 744, in lecture_fichier
    donnees_na = pd.read_csv(path_data_frame, sep='\t', header=0)
  File "/home/kevin/.local/lib/python3.6/site-packages/pandas/io/parsers.py", line 702, in parser_f
    return _read(filepath_or_buffer, kwds)
  File "/home/kevin/.local/lib/python3.6/site-packages/pandas/io/parsers.py", line 429, in _read
    parser = TextFileReader(filepath_or_buffer, **kwds)
  File "/home/kevin/.local/lib/python3.6/site-packages/pandas/io/parsers.py", line 895, in __init__
    self._make_engine(self.engine)
  File "/home/kevin/.local/lib/python3.6/site-packages/pandas/io/parsers.py", line 1122, in _make_engine
    self._engine = CParserWrapper(self.f, **self.options)
  File "/home/kevin/.local/lib/python3.6/site-packages/pandas/io/parsers.py", line 1853, in __init__
    self._reader = parsers.TextReader(src, **kwds)
  File "pandas/_libs/parsers.pyx", line 387, in pandas._libs.parsers.TextReader.__cinit__
  File "pandas/_libs/parsers.pyx", line 705, in pandas._libs.parsers.TextReader._setup_parser_source
FileNotFoundError: [Errno 2] File b'2018-03-27 foetus 90-10_PP16.txt' does not exist: b'2018-03-27 foetus 90-10_PP16.txt'
